Workbook
Name Slicer_Status: #N/A
Name Slicer_Type: #N/A
Name Slicer_Type1: #N/A
Name Slicer_Type2: #N/A
Name Slicer_Type3: #N/A

Sheet Overview
C2: Overview | F2: =HYPERLINK("#" & "Running!G2","Running") -> Running | I2: =HYPERLINK("#" & "Parking!K2","Parking") -> Parking | L2: =HYPERLINK("#" & "Advantis!L2","Advantis") -> Advantis | O2: =HYPERLINK("#" & "Services!A1","Service") -> Service
AA5: Count of Type | AB5: Type
AA6: Diameter | AB6: HIE | AC6: Grand Total
AA7: 12 | AB7: 4 | AC7: 4
AA8: 13 | AB8: 7 | AC8: 7
E9: TOTAL | G9: =E13+E16+E19+I13+I16 -> 294 | AA9: 14 | AB9: 4 | AC9: 4
AA10: 15 | AB10: 2 | AC10: 2
AA11: 16 | AB11: 9 | AC11: 9
AA12: 17 | AB12: 4 | AC12: 4
C13: TOP2V | E13: =COUNTIF(Machines!E:E,"TOP2V") -> 157 | G13: TOP2 | I13: =COUNTIF(Machines!E:E,"TOP2") -> 28 | AA13: 18 | AB13: 7 | AC13: 7
AA14: 19 | AB14: 4 | AC14: 4
AA15: 20 | AB15: 2 | AC15: 2
C16: HIE | E16: =COUNTIF(Machines!E:E,"HIE") -> 43 | G16: TR1S | I16: =COUNTIF(Machines!E:E,"TR1S") -> 19 | AA16: Grand Total | AB16: 43 | AC16: 43
C19: TR | E19: =COUNTIF(Machines!E:E,"TR") -> 47

Sheet Running
C2: =HYPERLINK("#" & "Overview!D2","Overview") -> Overview | F2: =HYPERLINK("#" & "Running!G2","Running") -> Running | I2: =HYPERLINK("#" & "Parking!K2","Parking") -> Parking | L2: =HYPERLINK("#" & "Advantis!L2","Advantis") -> Advantis | O2: =HYPERLINK("#" & "Services!A1","Service") -> Service
E9: RUNNING | G9: =COUNTIF(Machines!G:G,"Active") -> 276
C13: TOP2V | E13: =COUNTIFS(Machines!E:E,"TOP2V",Machines!G:G,"Active") -> 157 | G13: TOP2 | I13: =COUNTIFS(Machines!E:E,"TOP2",Machines!G:G,"Active") -> 19
C16: HIE | E16: =COUNTIFS(Machines!E:E,"HIE",Machines!G:G,"Active") -> 42 | G16: TR1S | I16: =COUNTIFS(Machines!E:E,"TR1S",Machines!G:G,"Active") -> 19
C19: TR | E19: =COUNTIFS(Machines!E:E,"TR",Machines!G:G,"Active") -> 39
S38: Status | T38: Type | U38: Count of Location Group
S39: Active | T39: HIE | U39: 42
T40: TOP2 | U40: 19
T41: TOP2V | U41: 157
T42: TR | U42: 39
T43: TR1S | U43: 19
S44: Grand Total | U44: 276

Sheet Parking
C2: =HYPERLINK("#" & "Overview!D2","Overview") -> Overview | F2: =HYPERLINK("#" & "Running!G2","Running") -> Running | I2: Parking | L2: =HYPERLINK("#" & "Advantis!L2","Advantis") -> Advantis | O2: =HYPERLINK("#" & "Services!A1","Service") -> Service
E9: PARKING TOTAL | G9: =E13+E16+I13+F21 -> 18
C13: BATCH PARKING | E13: =COUNTIF(Machines!F:F,"Batch Parking") -> 7 | G13: TRAINING (M/C) | I13: =COUNTIF(Machines!F:F,"Training (M/C)") -> 1
C16: PATHWAY PARKING | E16: =COUNTIF(Machines!F:F,"Pathway Parking") -> 10
W49: Count of Location Group | Y49: Type
W50: Status | X50: Location Group | Y50: HIE | Z50: TOP2 | AA50: TR | AB50: Grand Total
W51: Idle | X51: Batch Parking | Y51: 1 | AA51: 6 | AB51: 7
X52: Pathway Parking | Z52: 8 | AA52: 2 | AB52: 10
X53: Training (M/C) | Z53: 1 | AB53: 1
W54: Idle Total | Y54: 1 | Z54: 9 | AA54: 8 | AB54: 18

Sheet Advantis
C2: =HYPERLINK("#" & "Overview!D2","Overview") -> Overview | F2: =HYPERLINK("#" & "Running!G2","Running") -> Running | I2: =HYPERLINK("#" & "Parking!K2","Parking") -> Parking | L2: Advantis | O2: =HYPERLINK("#" & "Services!A1","Service") -> Service
E8: ADVANTIS MOTHBALL | G8: =COUNTIF('Advantis Machines'!G:G,"Advantis Mothball") -> 12
C12: TOP2 | E12: =COUNTIFS('Advantis Machines'!F:F,"TOP2",'Advantis Machines'!G:G,"Advantis Mothball") -> 7 | G12: TOP | I12: =COUNTIFS('Advantis Machines'!F:F,"TOP",'Advantis Machines'!G:G,"Advantis Mothball") -> 1
C16: HIE | E16: =COUNTIFS('Advantis Machines'!F:F,"HIE",'Advantis Machines'!G:G,"Advantis Mothball") -> 2 | G16: EVO4J | I16: =COUNTIFS('Advantis Machines'!F:F,"EVO4J",'Advantis Machines'!G:G,"Advantis Mothball") -> 2
S43: Count of Type | U43: Type | AC43: Count of Type | AD43: Type
S44: Diameter | T44: Current Location | U44: TOP2 | V44: Grand Total | AC44: Current Location | AD44: EVO4J | AE44: HIE | AF44: TOP | AG44: TOP2 | AH44: Grand Total
S45: 13 | T45: Advantis Mothball | U45: 1 | V45: 1 | AC45: Advantis Mothball | AD45: 2 | AE45: 2 | AF45: 1 | AG45: 7 | AH45: 12
S46: 13 Total | U46: 1 | V46: 1 | AC46: Grand Total | AD46: 2 | AE46: 2 | AF46: 1 | AG46: 7 | AH46: 12
S47: 14 | T47: Advantis Mothball | U47: 1 | V47: 1
S48: 14 Total | U48: 1 | V48: 1
S49: 15 | T49: Advantis Mothball | U49: 3 | V49: 3
S50: 15 Total | U50: 3 | V50: 3
S51: 17 | T51: Advantis Mothball | U51: 2 | V51: 2
S52: 17 Total | U52: 2 | V52: 2
S53: Grand Total | U53: 7 | V53: 7

Sheet Services
A1: Machine No | B1: Serial No | C1: M/C Year | D1: Machine Type | E1: Location Group | F1: Comments
A2: 2025 | B2: 8020936 | C2: 2022 | D2: TOP2V | E2: DEV (18) | F2: Scheduled Service Date- 2024.01.23 Service Date- 2024.02.12 Next Service Date- 2025.02.12 Check List Number - 25
A3: 2023 | B3: 8016221 | C3: 2013 | D3: HIE | E3: DEV (18) | F3: Scheduled Service Date- 2024.04.27 Service Date- 2024.05.02 Next Service Date- 2025.05.02 Check List Number -76
A4: 16110 | B4: 8016043 | C4: 2013 | D4: HIE | E4: DEV (18) | F4: Scheduled Service Date- 2024.03.19 Service Date- 2024.06.16 Next Service Date- 2025.06.16 Check List Number -114
A5: 1784 | B5: 8017966 | C5: 2017 | D5: TOP2V | E5: 1 | F5: Scheduled Service Date- 2024.02.26 Service Date- 2024.03.31 Next Service Date- 2025.03.31 Check List Number - 56
A6: 1315 | B6: 8015277 | C6: 2012 | D6: HIE | E6: 1 | F6: Scheduled Service Date- 2024.04.01 Service Date- 2024.04.08 Next Service Date- 2025.04.08 Check List Number -60
A7: 1778 | B7: 8019095 | C7: 2019 | D7: TOP2V | E7: 1 | F7: Scheduled Service Date- 2024.04.05 Service Date- 2024.04.21 Next Service Date- 2025.04.21 Check List Number -70
A8: 17104 | B8: 8018466 | C8: 2018 | D8: TOP2V | E8: 1 | F8: Scheduled Service Date- 2024.04.03 Service Date- 2024.04.03 Next Service Date- 2025.04.03 Check List Number -58
A9: 1864 | B9: 8019104 | C9: 2019 | D9: TOP2V | E9: 1 | F9: Scheduled Service Date- 2024.05.09 Service Date- 2024.05.12 Next Service Date- 2025.05.12 Check List Number -84
A10: 1394 | B10: 8015927 | C10: 2013 | D10: HIE | E10: 2 | F10: Scheduled Service Date- 2024.01.31 Service Date- 2024.02.06 Next Service Date- 2025.02.06 Check List Number - 22
A11: 1865 | B11: 8019105 | C11: 2019 | D11: TOP2V | E11: 2 | F11: Scheduled Service Date- 2024.03.04 Service Date- 2024.03.18 Next Service Date- 2025.03.18 Check List Number - 47
A12: 17107 | B12: 8017230 | C12: 2015 | D12: TOP2V | E12: 2 | F12: Scheduled Service Date- 2024.02.29 Service Date- 2024.03.01 Next Service Date- 2025.03.01 Check List Number - 36
A13: 16116 | B13: 8005185 | C13: 2002 | D13: TOP2 | E13: 2 | F13: Scheduled Service Date- 2024.01.22 Service Date- 2024.01.30 Next Service Date- 2025.01.30 Check List Number - 16
A14: 1883 | B14: 8018369 | C14: 2018 | D14: TOP2V | E14: 3 | F14: Scheduled Service Date- 2024.02.10 Service Date- 2024.02.02 Next Service Date- 2025.02.02 Check List Number - 20
A15: 1252 | B15: 8021186 | C15: 2022 | D15: TOP2V | E15: 3 | F15: Scheduled Service Date- 2024.02.08 Service Date- 2024.02.15 Next Service Date- 2025.02.15 Check List Number - 27
A16: 17108 | B16: 8017243 | C16: 2015 | D16: TOP2V | E16: 3 | F16: Scheduled Service Date- 2024.05.11 Service Date- 2024.05.11 Next Service Date- 2025.05.11 Check List Number -83
A17: 1470 | B17: 8019111 | C17: 2019 | D17: TOP2V | E17: 3 | F17: Scheduled Service Date- 2024.05.06 Service Date- 2024.06.03 Next Service Date- 2025.06.03 Check List Number -170
A18: D-21 | B18: 8017229 | C18: 2015 | D18: TOP2V | E18: 3 | F18: Scheduled Service Date- 2024.04.02 Service Date- 2024.04.02 Next Service Date- 2025.04.02 Check List Number -57
A19: 1472 | B19: 8017961 | C19: 2017 | D19: TOP2V | E19: 4 | F19: Scheduled Service Date- 2024.04.29 Service Date- 2024.04.15 Next Service Date- 2025.04.15 Check List Number -66
A20: 16120 | B20: -8020832 | C20: 2022 | D20: TOP2V | E20: 4 | F20: Scheduled Service Date- 2024.05.02 Service Date- 2024.05.02 Next Service Date- 2025.05.02 Check List Number -77
A21: 1966 | B21: -8021544 | C21: 2022 | D21: TOP2V | E21: 4 | F21: Scheduled Service Date- 2024.04.30 Service Date- 2024.04.15 Next Service Date- 2025.04.15 Check List Number -67
A22: 1477 | B22: 8019107 | C22: 2019 | D22: TOP2V | E22: 4 | F22: Scheduled Service Date- 2024.05.17 Service Date- 2024.05.21 Next Service Date- 2025.05.21 Check List Number - 93
A23: 1485 | B23: 8019108 | C23: 2019 | D23: TOP2V | E23: 4 | F23: Scheduled Service Date- 2024.02.02 Service Date- 2024.01.25 Next Service Date- 2025.01.25 Check List Number - 08
A24: 1683 | B24: 8019117 | C24: 2019 | D24: TOP2V | E24: 5 | F24: Scheduled Service Date- 2024.02.05 Service Date- 2024.02.05 Next Service Date- 2025.02.05 Check List Number - 21
A25: 16123 | B25: 8021172 | C25: 2022 | D25: TOP2V | E25: 5 | F25: Scheduled Service Date- 2024.05.18 Service Date- 2024.05.03 Next Service Date- 2025.05.03 Check List Number -78
A26: 1689 | B26: 8019094 | C26: 2019 | D26: TOP2V | E26: 5 | F26: Scheduled Service Date- 2024.04.06 Service Date- 2024.04.06 Next Service Date- 2025.04.06 Check List Number -59
A27: 15124 | B27: -8018413 | C27: 2018 | D27: TOP2V | E27: 5 | F27: Scheduled Service Date- 2024.01.05 Service Date- 2024.01.27 Next Service Date- 2025.01.27 Check List Number -11
A28: 1108 | B28: 8019014 | C28: 2019 | D28: TOP2V | E28: 6 | F28: Scheduled Service Date- 2024.01.12 Service Date- 2024.01.21 Next Service Date- 2025.01.21 Check List Number - 06
A29: 1694 | B29: -8017988 | C29: 2017 | D29: TOP2V | E29: 6 | F29: Scheduled Service Date- 2024.05.13 Service Date- 2024.03.16 Next Service Date- 2025.03.16 Check List Number -46
A30: 1580 | B30: 8017964 | C30: 2017 | D30: TOP2V | E30: 6 | F30: Scheduled Service Date- 2024.05.14 Service Date- 2024.03.11 Next Service Date- 2025.03.11 Check List Number -44
... A51: 1895 | B51: 8020955 | C51: 2022 | D51: TOP2V | E51: 10 | F51: Scheduled Service Date- 2024.05.07 Service Date- 2024.05.20 Next Service Date- 2025.05.20 Check List Number -92
A52: 21TR02 | B52: 8021022 | C52: 2022 | D52: TR1S | E52: 11 | F52: Scheduled Service Date- 2024.03.05 Service Date- 2024.03.05 Next Service Date- 2025.03.05 Check List Number - 40
A53: 1938 | B53: 8018157 | C53: 2017 | D53: TOP2V | E53: 11 | F53: Scheduled Service Date- 2024.02.28 Service Date- 202402.24 Next Service Date- 2025.02.24 Check List Number - 33
A54: 16101 | B54: -8017235 | C54: 2015 | D54: TOP2V | E54: 11 | F54: Scheduled Service Date- 2024.04.23 Service Date- 2024.05.06 Next Service Date- 2025.05.06 Check List Number -108
A55: 2114 | B55: -8017434 | C55: 2015 | D55: TOP2V | E55: 11 | F55: ENG:
A56: 15125 | B56: 8018708 | C56: 2018 | D56: TOP2V | E56: 11 | F56: Scheduled Service Date- 2024.04.25 Service Date- 2024.04.24 Next Service Date- 2025.04.24 Check List Number -71
A57: 1948 | B57: 8045967/8015967 | C57: 2013 | D57: HIE | E57: 12 | F57: Scheduled Service Date- 2024.05.11 Service Date- 2024.03.11 Next Service Date- 2025.03.11 Check List Number - 43
A58: 2027 | B58: 8016046 | C58: 2013 | D58: HIE | E58: 12 | F58: Scheduled Service Date- 2024.03.20 Service Date- 2024.03.25 Next Service Date- 2025.03.25 Check List Number -50
A59: 16112 | B59: 8015602 | C59: 2013 | D59: HIE | E59: 12 | F59: Scheduled Service Date- 2024.05.15 Service Date- 2024.03.15 Next Service Date- 2025.03.15 Check List Number -45
A60: 1249 | B60: 8014332 | C60: 2011 | D60: HIE | E60: 12 | F60: Scheduled Service Date- 2024.02.27 Service Date- 2024.02.24 Next Service Date- 2025.02.24 Check List Number - 32
...

Sheet Machines
A1: Machine No | B1: Serial No | C1: M/C Year | D1: Diameter | E1: Type | F1: Location Group | G1: Status | H1: Service Date
A2: 2025 (F W) | B2: 8020936 | C2: 2022 | D2: 20 | E2: TOP2V | F2: DEV (18) | G2: Active | H2: 45700
A3: 2023 (F S) | B3: 8016221 | C3: 2013 | D3: 20 | E3: HIE | F3: DEV (18) | G3: Active | H3: 45769 | J3: M | K3: Mobile Stepper Motor
A4: 1947 (F S) | B4: 8015556 | C4: 2012 | D4: 19 | E4: HIE | F4: DEV (18) | G4: Active | H4: 45723 | J4: F | K4: Fix Stepper Motor
A5: 1450 (F S) | B5: 8015749 | C5: 2013 | D5: 14 | E5: HIE | F5: DEV (18) | G5: Active | H5: 45646 | J5: S | K5: Santoni Pattern Drum
A6: 1693 (F S) | B6: 8015606 | C6: 2013 | D6: 16 | E6: HIE | F6: DEV (18) | G6: Active | H6: 45866 | J6: W | K6: Wack Pattern Drum
A7: 15135 (F W) | B7: 8004605 | C7: 2001 | D7: 15 | E7: TOP2 | F7: DEV (18) | G7: Active | H7: 45668 | J7: H | K7: Half Moon
A8: D-17 (H M S) | B8: 8013492 | C8: 2010 | D8: 17 | E8: HIE | F8: DEV (18) | G8: Active | H8: 45896
A9: 1822 (F S) | B9: 8015522 | C9: 2012 | D9: 18 | E9: HIE | F9: DEV (18) | G9: Active | H9: 45859
A10: 1387 (F S) | B10: 8015837 | C10: 2013 | D10: 13 | E10: HIE | F10: DEV (18) | G10: Active | H10: 45918
A11: 1590 (H F S) | B11: 8014553 | C11: 2011 | D11: 15 | E11: HIE | F11: DEV (18) | G11: Active | H11: 45654
A12: 1213 (F S) | B12: 8016050 | C12: 2013 | D12: 12 | E12: HIE | F12: DEV (18) | G12: Active | H12: 45895
A13: 16110 (F S) | B13: 8016043 | C13: 2013 | D13: 16 | E13: HIE | F13: DEV (18) | G13: Active | H13: 45826
A14: 1799 (M W) | B14: 8018469 | C14: 2018 | D14: 17 | E14: TOP2V | F14: 1 | G14: Active | H14: 45735
A15: 1784 (F W) | B15: 8017966 | C15: 2017 | D15: 17 | E15: TOP2V | F15: 1 | G15: Active | H15: 45742
A16: 1315 (F S) | B16: 8015277 | C16: 2012 | D16: 13 | E16: HIE | F16: 1 | G16: Active | H16: 45747
A17: 1778 (M W) | B17: 8019095 | C17: 2019 | D17: 17 | E17: TOP2V | F17: 1 | G17: Active | H17: 45755
A18: 17104 (M W) | B18: 8018466 | C18: 2018 | D18: 17 | E18: TOP2V | F18: 1 | G18: Active | H18: 45747
A19: 1780 ( F E ) | B19: 8018272 | C19: 2017 | D19: 17 | E19: TOP2V | F19: 1 | G19: Active | H19: 45613
A20: 1689 (M W) | B20: 8019094 | C20: 2019 | D20: 16 | E20: TOP2V | F20: 1 | G20: Active | H20: 45754
A21: 1688 (M W) | B21: 8019116 | C21: 2019 | D21: 16 | E21: TOP2V | F21: 1 | G21: Active | H21: 45922
A22: 1788 (M S) | B22: 8009086 | C22: 2005 | D22: 17 | E22: TOP2 | F22: 1 | G22: Active | H22: 45645
A23: 17106 (F W) | B23: 8017240 | C23: 2015 | D23: 17 | E23: TOP2V | F23: 1 | G23: Active | H23: 45538
A24: 1586 (F W) | B24: 8018269 | C24: 2017 | D24: 15 | E24: TOP2V | F24: 1 | G24: Active | H24: 45926
A25: 1964 (M W) | B25: 8021543 | C25: 2022 | D25: 19 | E25: TOP2V | F25: 1 | G25: Active | H25: 45891
A26: 17116 (M W) | B26: 8006106 | C26: 2003 | D26: 17 | E26: TOP2 | F26: 2 | G26: Active | H26: 45667
B27: 8021599 | D27: 16 | E27: TR1S | F27: 2 | G27: Active
A28: 17109 (M W) | B28: 8006181 | C28: 2003 | D28: 17 | E28: TOP2 | F28: 2 | G28: Active | H28: 45649
A29: 1394 (F S) | B29: 8015927 | C29: 2013 | D29: 13 | E29: HIE | F29: 2 | G29: Active | H29: 45691
A30: 1865 (M W) | B30: 8019105 | C30: 2019 | D30: 18 | E30: TOP2V | F30: 2 | G30: Active | H30: 45730
A31: 1371 (F W) | B31: 8017955 | C31: 2017 | D31: 13 | E31: TOP2V | F31: 2 | G31: Active | H31: 45880
A32: 17110 (M W) | B32: 8006107 | C32: 2003 | D32: 17 | E32: TOP2 | F32: 2 | G32: Active | H32: 45648
A33: 17107 (F W) | B33: 8017230 | C33: 2015 | D33: 17 | E33: TOP2V | F33: 2 | G33: Active | H33: 45714
A34: 1867 (F W) | B34: 8018975 | C34: 2019 | D34: 18 | E34: TOP2V | F34: 2 | G34: Active | H34: 45675
A35: 1893 (F W) | B35: 8020934 | C35: 2022 | D35: 18 | E35: TOP2V | F35: 2 | G35: Active | H35: 45918
A36: 1381 (F W) | B36: 8019237 | C36: 2020 | D36: 13 | E36: TOP2V | F36: 2 | G36: Active | H36: 45787
A37: 1685 (F W) | B37: 8018388 | C37: 2018 | D37: 16 | E37: TOP2V | F37: 2 | G37: Active | H37: 45899
A38: 1472 (F W) | B38: 8017961 | C38: 2017 | D38: 14 | E38: TOP2V | F38: 3 | G38: Active | H38: 45775
A39: 2034 (M W) | B39: 8021545 | C39: 2022 | D39: 20 | E39: TOP2V | F39: 3 | G39: Active | H39: 46027
... A65: 16123 (F W) | B65: 8021172 | C65: 2022 | D65: 16 | E65: TOP2V | F65: 5 | G65: Active | H65: 45779
...

Sheet Advantis Machines
A1: Machine No | B1: Serial No | C1: M/C Inhouse Date | D1: M/C Year | E1: Diameter | F1: Type | G1: Current Location
A2: 1386 | B2: 8004818 | D2: 2002 | E2: 13 | F2: TOP2 | G2: Advantis Mothball
A3: 1483 (H M S) | B3: 8011191 | D3: 2007 | E3: 14 | F3: HIE | G3: Advantis Mothball
A4: 1482 | B4: 8016709 | D4: 2014 | E4: 14 | F4: HIE | G4: Advantis Mothball
A5: 1494 (F W) | B5: 8004767 | D5: 2001 | E5: 14 | F5: TOP2 | G5: Advantis Mothball
A6: 15132 | B6: 8007261 | D6: 2003 | E6: 15 | F6: TOP2 | G6: Advantis Mothball
A7: 1513 | B7: 8005186 | D7: 2002 | E7: 15 | F7: TOP2 | G7: Advantis Mothball
A8: 15142 (M W) | B8: 8008496 | D8: 2004 | E8: 15 | F8: TOP2 | G8: Advantis Mothball
A9: 1706 | B9: 8010477 | D9: 2012 | E9: 17 | F9: TOP2 | G9: Advantis Mothball
A10: 17111 (M S) | B10: 8010052 | D10: 2005 | E10: 17 | F10: TOP2 | G10: Advantis Mothball
A11: Evo(15New02) (M S) | B11: 8016516 | D11: 2014 | E11: 15 | F11: EVO4J | G11: Advantis Mothball
A12: 17TR22(EVO4J) (F S) | B12: 8017991 | D12: 2017 | E12: 17 | F12: EVO4J | G12: Advantis Mothball
A13: TOP1 | B13: 8003064 | D13: 2000 | E13: 13 | F13: TOP | G13: Advantis Mothball

Sheet OUT
A1: Machine No | B1: Serial No | C1: M/C Year | D1: Diameter | E1: Type | F1: Current Location
A2: 1386 | B2: 8004818 | C2: 2002 | D2: 13 | E2: TOP2 | F2: Advantis Mothball
A3: 1483 (H M S) | B3: 8011191 | C3: 2007 | D3: 14 | E3: HIE | F3: Advantis Mothball
A4: 1482 | B4: 8016709 | C4: 2014 | D4: 14 | E4: HIE | F4: Advantis Mothball
A5: 1494 (F W) | B5: 8004767 | C5: 2001 | D5: 14 | E5: TOP2 | F5: Advantis Mothball
A6: 15132 | B6: 8007261 | C6: 2003 | D6: 15 | E6: TOP2 | F6: Advantis Mothball
A7: 1513 | B7: 8005186 | C7: 2002 | D7: 15 | E7: TOP2 | F7: Advantis Mothball
A8: 15142 (M W) | B8: 8008496 | C8: 2004 | D8: 15 | E8: TOP2 | F8: Advantis Mothball
A9: 1706 | B9: 8010477 | C9: 2012 | D9: 17 | E9: TOP2 | F9: Advantis Mothball
A10: 17111 (M S) | B10: 8010052 | C10: 2005 | D10: 17 | E10: TOP2 | F10: Advantis Mothball
A11: 15New02(EVO4J) (M S) | B11: 8016516 | C11: 2014 | D11: 15 | E11: EVO4J | F11: Advantis Mothball
A12: 1722(EVO4J) (F S) | B12: 8017991 | C12: 2017 | D12: 17 | E12: EVO4J | F12: Advantis Mothball
A13: TOP1 | B13: 8003064 | C13: 2000 | D13: 13 | E13: TOP | F13: Advantis Mothball
A14: 15(40 Gage) | B14: 8018413 | C14: 2017 | D14: 15 | E14: Top2V40G | F14: LI-01
A15: 14(40 Gage) | B15: 8017981 | C15: 2017 | D15: 14 | E15: Top2V40G | F15: LI-01

Sheet Machine Details
A1: Machine No | B1: Serial No | C1: M/C Year | D1: Diameter | E1: Type
A2: 2025 | B2: 8020936 | C2: 2022 | D2: 20 | E2: Top2v
A3: 2023 | B3: 8016221 | C3: 2013 | D3: 20 | E3: Hie
A4: 1947 | B4: 8015556 | C4: 2012 | D4: 19 | E4: Hie
A5: 1450 | B5: 8015749 | C5: 2013 | D5: 14 | E5: Hie
A6: 1693 | B6: 8015606 | C6: 2013 | D6: 16 | E6: Hie
A7: 15135 | B7: 8004605 | C7: 2001 | D7: 15 | E7: Top2
A8: D-17 | B8: 8013492 | C8: 2010 | D8: 17 | E8: Hie
A9: 1822 | B9: 8015522 | C9: 2012 | D9: 18 | E9: Hie
A10: 1387 | B10: 8015837 | C10: 2013 | D10: 13 | E10: Hie
A11: 1590 | B11: 8014553 | C11: 2011 | D11: 15 | E11: Hie
A12: 1213 | B12: 8016050 | C12: 2013 | D12: 12 | E12: Hie
A13: 16110 | B13: 8016043 | C13: 2013 | D13: 16 | E13: Hie
A14: 1799 | B14: 8018469 | C14: 2018 | D14: 17 | E14: Top2v
A15: 1784 | B15: 8017966 | C15: 2017 | D15: 17 | E15: Top2v
A16: 1315 | B16: 8015277 | C16: 2012 | D16: 13 | E16: Hie
A17: 1778 | B17: 8019095 | C17: 2019 | D17: 17 | E17: Top2v
A18: 17104 | B18: 8018466 | C18: 2018 | D18: 17 | E18: Top2v
A19: 1780 | B19: 8018272 | C19: 2017 | D19: 17 | E19: Top2v
A20: 1869 | B20: 8018154 | C20: 2017 | D20: 18 | E20: Top2v
... A48: 1470 | B48: 8019111 | C48: 2019 | D48: 14 | E48: Top2v
A49: D-21 | B49: 8017229 | C49: 2015 | D49: 21 | E49: Top2v
A50: 1472 | B50: 8017961 | C50: 2017 | D50: 14 | E50: Top2v
A51: 1486 | B51: 8019243 | C51: 2020 | D51: 14 | E51: Top2v
A52: 16120 | B52: 8020832 | C52: 2022 | D52: 16 | E52: Top2v
A53: 1491 | B53: 8019241 | C53: 2020 | D53: 14 | E53: Top2v
A54: 1468 | B54: 8017959 | C54: 2017 | D54: 14 | E54: Top2v
A55: 1952 | B55: 8020823 | C55: 2022 | D55: 19 | E55: Top2v
A56: 1966 | B56: 8021544 | C56: 2022 | D56: 19 | E56: Top2v
A57: 1477 | B57: 8019107 | C57: 2019 | D57: 14 | E57: Top2v
A58: 1882 | B58: 8018811 | C58: 2019 | D58: 18 | E58: Top2v
A59: 1485 | B59: 8019108 | C59: 2019 | D59: 14 | E59: Top2v
A60: 1515 | B60: 8017963 | C60: 2017 | D60: 15 | E60: Top2v
A61: 22New | B61: 8020933 | C61: 2022 | D61: 22 | E61: Top2v
A62: 1586 | B62: 8018269 | C62: 2017 | D62: 15 | E62: Top2v
A63: 1588 | B63: 8019092 | C63: 2019 | D63: 15 | E63: Top2v
A64: 1683 | B64: 8019117 | C64: 2019 | D64: 16 | E64: Top2v
A65: 16123 | B65: 8021172 | C65: 2022 | D65: 16 | E65: Top2v
A66: 16122 | B66: 8021171 | C66: 2022 | D66: 16 | E66: Top2v
A67: 1689 | B67: 8019094 | C67: 2019 | D67: 16 | E67: Top2v
...

Sheet TypeDiameter
A1: Type | B1: Diameter | C1: Count
A2: Hie | B2: 12 | C2: 4
A3: Hie | B3: 13 | C3: 8
A4: Hie | B4: 14 | C4: 6
A5: Hie | B5: 15 | C5: 2
A6: Hie | B6: 16 | C6: 9
A7: Hie | B7: 17 | C7: 3
A8: Hie | B8: 18 | C8: 7
A9: Hie | B9: 19 | C9: 4
A10: Hie | B10: 20 | C10: 2
A11: Top2 | B11: 13 | C11: 2
A12: Top2 | B12: 14 | C12: 2
A13: Top2 | B13: 15 | C13: 12
... A46: Top | B46: 13 | C46: 1

Sheet Legend
A1: M/C Batch Layot
E2: TOP2V | G2: Google Blue (#4285F4)
A3: Dev (18) | B3: 17 | E3: HIE | G3: lavender purple (#ad7fe6)
A4: 1 | B4: 18 | E4: TOP2 | G4: Celery Stick (#b5c665)
A5: 2 | B5: 19 | E5: TR | G5: Atomic Tangerine (#F59E52)
A6: 3 | B6: 20 | E6: TR1S | G6: Bright Cyan (#2bb8ca)
A7: 4 | B7: 21 | E7: TOP2V40G | G7: Golden Fizz (#eac43b)
A8: 5 | B8: 22 | E8: TOP | G8: Mystic Iris (#6666ba)
A9: 6 | B9: 23 | E9: EVO4J | G9: Candy Pink (#e574b1)
A10: 7
A11: 8 | B11: TR Parking (Bacth Parking) | C11: Parking (Pathway Parking)
A12: 9
A13: 10 | B13: Training (M/C)
A14: 11
A15: 12
A16: 13
A17: 14
A18: 15
A19: 16
A21: From Knitting Machine Excel sheet by Janaka
A22: Link | B22: https://url.uk.m.mimecastprotect.com/s/CLrgCkwl8iOn340zi2fvUGHZcT?domain=docs.google.com
A24: Converted Machine
A25: Previously
A26: 15(40Gage) | B26: 8017982
A27: 15124 (M W) | B27: 8018413
A28: Now
A29: 15(40Gage) | B29: 8018413
A30: 15124 (M W) | B30: 8017982
